[2023-06-15 09:38:16,927 : INFO: main: Welcome to our custom logging]
[2023-06-15 10:20:39,291 : INFO: main: >>>> stage Data Ingestion stage started <<<<<]
[2023-06-15 10:20:39,299 : INFO: common: CSV file: config\config.yaml loaded successfully]
[2023-06-15 10:20:39,300 : ERROR: main: too many values to unpack (expected 2)]
Traceback (most recent call last):
  File "C:\Users\srena\Downloads\Movie_Recommendation_System\main.py", line 9, in <module>
    data_ingestion.main()
  File "c:\users\srena\downloads\movie_recommendation_system\src\Movie_Recommendation_System\pipeline\stage_01_data_ingestion.py", line 9, in main
    config = ConfigurationManager()
             ^^^^^^^^^^^^^^^^^^^^^^
  File "c:\users\srena\downloads\movie_recommendation_system\src\Movie_Recommendation_System\config\configuration.py", line 11, in __init__
    self.config = read_csv_file(config_filepath)
                  ^^^^^^^^^^^^^^^^^^^^^^^^^^^^^^
  File "C:\Users\srena\AppData\Roaming\Python\Python311\site-packages\ensure\main.py", line 849, in __call__
    return_val = self.f(*args, **kwargs)
                 ^^^^^^^^^^^^^^^^^^^^^^^
  File "c:\users\srena\downloads\movie_recommendation_system\src\Movie_Recommendation_System\utils\common.py", line 87, in read_csv_file
    raise e
  File "c:\users\srena\downloads\movie_recommendation_system\src\Movie_Recommendation_System\utils\common.py", line 82, in read_csv_file
    return ConfigBox(content)
           ^^^^^^^^^^^^^^^^^^
  File "C:\Users\srena\AppData\Roaming\Python\Python311\site-packages\box\box.py", line 256, in __init__
    for k, v in args[0]:
        ^^^^
ValueError: too many values to unpack (expected 2)
[2023-06-15 10:21:38,685 : INFO: main: >>>> stage Data Ingestion stage started <<<<<]
[2023-06-15 10:21:38,689 : INFO: common: CSV file: config\config.yaml loaded successfully]
[2023-06-15 10:21:38,690 : ERROR: main: too many values to unpack (expected 2)]
Traceback (most recent call last):
  File "C:\Users\srena\Downloads\Movie_Recommendation_System\main.py", line 9, in <module>
    data_ingestion.main()
  File "c:\users\srena\downloads\movie_recommendation_system\src\Movie_Recommendation_System\pipeline\stage_01_data_ingestion.py", line 9, in main
    config = ConfigurationManager()
             ^^^^^^^^^^^^^^^^^^^^^^
  File "c:\users\srena\downloads\movie_recommendation_system\src\Movie_Recommendation_System\config\configuration.py", line 11, in __init__
    self.config = read_csv_file(config_filepath)
                  ^^^^^^^^^^^^^^^^^^^^^^^^^^^^^^
  File "C:\Users\srena\AppData\Roaming\Python\Python311\site-packages\ensure\main.py", line 849, in __call__
    return_val = self.f(*args, **kwargs)
                 ^^^^^^^^^^^^^^^^^^^^^^^
  File "c:\users\srena\downloads\movie_recommendation_system\src\Movie_Recommendation_System\utils\common.py", line 87, in read_csv_file
    raise e
  File "c:\users\srena\downloads\movie_recommendation_system\src\Movie_Recommendation_System\utils\common.py", line 82, in read_csv_file
    return ConfigBox(content)
           ^^^^^^^^^^^^^^^^^^
  File "C:\Users\srena\AppData\Roaming\Python\Python311\site-packages\box\box.py", line 256, in __init__
    for k, v in args[0]:
        ^^^^
ValueError: too many values to unpack (expected 2)
[2023-06-15 10:29:46,758 : INFO: main: >>>> stage Data Ingestion stage started <<<<<]
[2023-06-15 10:29:46,760 : INFO: common: yaml file: config\config.yaml loaded successfully]
[2023-06-15 10:29:46,761 : INFO: common: yaml file: params.yaml loaded successfully]
[2023-06-15 10:29:46,762 : ERROR: main: yaml file is empty]
Traceback (most recent call last):
  File "c:\users\srena\downloads\movie_recommendation_system\src\Movie_Recommendation_System\utils\common.py", line 29, in read_yaml
    return ConfigBox(content)
           ^^^^^^^^^^^^^^^^^^
  File "C:\Users\srena\AppData\Roaming\Python\Python311\site-packages\box\box.py", line 259, in __init__
    raise BoxValueError("First argument must be mapping or iterable")
box.exceptions.BoxValueError: First argument must be mapping or iterable

During handling of the above exception, another exception occurred:

Traceback (most recent call last):
  File "C:\Users\srena\Downloads\Movie_Recommendation_System\main.py", line 9, in <module>
    data_ingestion.main()
  File "c:\users\srena\downloads\movie_recommendation_system\src\Movie_Recommendation_System\pipeline\stage_01_data_ingestion.py", line 9, in main
    config = ConfigurationManager()
             ^^^^^^^^^^^^^^^^^^^^^^
  File "c:\users\srena\downloads\movie_recommendation_system\src\Movie_Recommendation_System\config\configuration.py", line 12, in __init__
    self.params = read_yaml(params_filepath)
                  ^^^^^^^^^^^^^^^^^^^^^^^^^^
  File "C:\Users\srena\AppData\Roaming\Python\Python311\site-packages\ensure\main.py", line 849, in __call__
    return_val = self.f(*args, **kwargs)
                 ^^^^^^^^^^^^^^^^^^^^^^^
  File "c:\users\srena\downloads\movie_recommendation_system\src\Movie_Recommendation_System\utils\common.py", line 32, in read_yaml
    raise ValueError("yaml file is empty")
ValueError: yaml file is empty
[2023-06-15 10:30:13,842 : INFO: main: >>>> stage Data Ingestion stage started <<<<<]
[2023-06-15 10:30:13,844 : INFO: common: yaml file: config\config.yaml loaded successfully]
[2023-06-15 10:30:13,844 : INFO: common: yaml file: params.yaml loaded successfully]
[2023-06-15 10:30:13,845 : ERROR: main: "'ConfigBox' object has no attribute 'artifacts_root'"]
Traceback (most recent call last):
  File "C:\Users\srena\AppData\Roaming\Python\Python311\site-packages\box\box.py", line 503, in __getitem__
    return super().__getitem__(item)
           ^^^^^^^^^^^^^^^^^^^^^^^^^
KeyError: 'artifacts_root'

The above exception was the direct cause of the following exception:

Traceback (most recent call last):
  File "C:\Users\srena\AppData\Roaming\Python\Python311\site-packages\box\box.py", line 536, in __getattr__
    value = self.__getitem__(item, _ignore_default=True)
            ^^^^^^^^^^^^^^^^^^^^^^^^^^^^^^^^^^^^^^^^^^^^
  File "C:\Users\srena\AppData\Roaming\Python\Python311\site-packages\box\box.py", line 524, in __getitem__
    raise BoxKeyError(str(err)) from _exception_cause(err)
box.exceptions.BoxKeyError: "'artifacts_root'"

During handling of the above exception, another exception occurred:

Traceback (most recent call last):
  File "C:\Users\srena\AppData\Roaming\Python\Python311\site-packages\box\box.py", line 538, in __getattr__
    value = object.__getattribute__(self, item)
            ^^^^^^^^^^^^^^^^^^^^^^^^^^^^^^^^^^^
AttributeError: 'ConfigBox' object has no attribute 'artifacts_root'

The above exception was the direct cause of the following exception:

Traceback (most recent call last):
  File "C:\Users\srena\AppData\Roaming\Python\Python311\site-packages\box\config_box.py", line 28, in __getattr__
    return super().__getattr__(item)
           ^^^^^^^^^^^^^^^^^^^^^^^^^
  File "C:\Users\srena\AppData\Roaming\Python\Python311\site-packages\box\box.py", line 552, in __getattr__
    raise BoxKeyError(str(err)) from _exception_cause(err)
box.exceptions.BoxKeyError: "'ConfigBox' object has no attribute 'artifacts_root'"

During handling of the above exception, another exception occurred:

Traceback (most recent call last):
  File "C:\Users\srena\AppData\Roaming\Python\Python311\site-packages\box\box.py", line 503, in __getitem__
    return super().__getitem__(item)
           ^^^^^^^^^^^^^^^^^^^^^^^^^
KeyError: 'artifacts_root'

The above exception was the direct cause of the following exception:

Traceback (most recent call last):
  File "C:\Users\srena\AppData\Roaming\Python\Python311\site-packages\box\box.py", line 536, in __getattr__
    value = self.__getitem__(item, _ignore_default=True)
            ^^^^^^^^^^^^^^^^^^^^^^^^^^^^^^^^^^^^^^^^^^^^
  File "C:\Users\srena\AppData\Roaming\Python\Python311\site-packages\box\box.py", line 524, in __getitem__
    raise BoxKeyError(str(err)) from _exception_cause(err)
box.exceptions.BoxKeyError: "'artifacts_root'"

During handling of the above exception, another exception occurred:

Traceback (most recent call last):
  File "C:\Users\srena\AppData\Roaming\Python\Python311\site-packages\box\box.py", line 538, in __getattr__
    value = object.__getattribute__(self, item)
            ^^^^^^^^^^^^^^^^^^^^^^^^^^^^^^^^^^^
AttributeError: 'ConfigBox' object has no attribute 'artifacts_root'

The above exception was the direct cause of the following exception:

Traceback (most recent call last):
  File "C:\Users\srena\Downloads\Movie_Recommendation_System\main.py", line 9, in <module>
    data_ingestion.main()
  File "c:\users\srena\downloads\movie_recommendation_system\src\Movie_Recommendation_System\pipeline\stage_01_data_ingestion.py", line 9, in main
    config = ConfigurationManager()
             ^^^^^^^^^^^^^^^^^^^^^^
  File "c:\users\srena\downloads\movie_recommendation_system\src\Movie_Recommendation_System\config\configuration.py", line 14, in __init__
    create_directories([self.config.artifacts_root])
                        ^^^^^^^^^^^^^^^^^^^^^^^^^^
  File "C:\Users\srena\AppData\Roaming\Python\Python311\site-packages\box\config_box.py", line 30, in __getattr__
    return super().__getattr__(item.lower())
           ^^^^^^^^^^^^^^^^^^^^^^^^^^^^^^^^^
  File "C:\Users\srena\AppData\Roaming\Python\Python311\site-packages\box\box.py", line 552, in __getattr__
    raise BoxKeyError(str(err)) from _exception_cause(err)
box.exceptions.BoxKeyError: "'ConfigBox' object has no attribute 'artifacts_root'"
[2023-06-15 10:30:43,268 : INFO: main: >>>> stage Data Ingestion stage started <<<<<]
[2023-06-15 10:30:43,269 : INFO: common: yaml file: config\config.yaml loaded successfully]
[2023-06-15 10:30:43,270 : INFO: common: yaml file: params.yaml loaded successfully]
[2023-06-15 10:30:43,273 : INFO: common: Created directory at: recommendation_data]
[2023-06-15 10:30:43,274 : INFO: common: Created directory at: recommendation_data/data_ingestion]
[2023-06-15 10:30:45,402 : INFO: data_ingestion: recommendation_data/data_ingestion/data.zip download! with following info: 
Connection: close
Content-Length: 8842458
Cache-Control: max-age=300
Content-Security-Policy: default-src 'none'; style-src 'unsafe-inline'; sandbox
Content-Type: application/zip
ETag: "950db06cc1904f78fdb5f20b6743e7f2bcc988e04b790bd45a2cb7a676ec7ecf"
Strict-Transport-Security: max-age=31536000
X-Content-Type-Options: nosniff
X-Frame-Options: deny
X-XSS-Protection: 1; mode=block
X-GitHub-Request-Id: 1616:928F:2E6673:3734C6:648A9AFA
Accept-Ranges: bytes
Date: Thu, 15 Jun 2023 05:00:43 GMT
Via: 1.1 varnish
X-Served-By: cache-maa10232-MAA
X-Cache: MISS
X-Cache-Hits: 0
X-Timer: S1686805243.602001,VS0,VE819
Vary: Authorization,Accept-Encoding,Origin
Access-Control-Allow-Origin: *
Cross-Origin-Resource-Policy: cross-origin
X-Fastly-Request-ID: 7ca461f88f8be33fa4548ba10c053bb6a8d02281
Expires: Thu, 15 Jun 2023 05:05:43 GMT
Source-Age: 0

]
[2023-06-15 10:30:45,719 : INFO: main: >>>>>> stage Data Ingestion stage completed <<<<<<<<

x===========x]
[2023-06-15 10:32:46,237 : INFO: main: >>>> stage Data Ingestion stage started <<<<<]
[2023-06-15 10:32:46,239 : INFO: common: yaml file: config\config.yaml loaded successfully]
[2023-06-15 10:32:46,242 : INFO: common: yaml file: params.yaml loaded successfully]
[2023-06-15 10:32:46,243 : INFO: common: Created directory at: recommendation_data]
[2023-06-15 10:32:46,244 : INFO: common: Created directory at: recommendation_data/data_ingestion]
[2023-06-15 10:32:47,481 : INFO: data_ingestion: recommendation_data/data_ingestion/data.zip download! with following info: 
Connection: close
Content-Length: 8842458
Cache-Control: max-age=300
Content-Security-Policy: default-src 'none'; style-src 'unsafe-inline'; sandbox
Content-Type: application/zip
ETag: "950db06cc1904f78fdb5f20b6743e7f2bcc988e04b790bd45a2cb7a676ec7ecf"
Strict-Transport-Security: max-age=31536000
X-Content-Type-Options: nosniff
X-Frame-Options: deny
X-XSS-Protection: 1; mode=block
X-GitHub-Request-Id: 1616:928F:2E6673:3734C6:648A9AFA
Accept-Ranges: bytes
Date: Thu, 15 Jun 2023 05:02:45 GMT
Via: 1.1 varnish
X-Served-By: cache-maa10234-MAA
X-Cache: HIT
X-Cache-Hits: 0
X-Timer: S1686805365.400158,VS0,VE1
Vary: Authorization,Accept-Encoding,Origin
Access-Control-Allow-Origin: *
Cross-Origin-Resource-Policy: cross-origin
X-Fastly-Request-ID: 0f65163cc91129ee8714b8ad009edf49a28a243a
Expires: Thu, 15 Jun 2023 05:07:45 GMT
Source-Age: 122

]
[2023-06-15 10:32:47,788 : INFO: main: >>>>>> stage Data Ingestion stage completed <<<<<<<<

x===========x]
